Workbook
Name Alpha: Params!$C$7
Name AsOfDate: Params!$C$5
Name BasisFactor: Params!$C$16
Name BusinessDaysPerYear: Params!$C$10
Name DaysPerYear: Params!$C$9
Name FX_Table: Params!$A$56:$C$61
Name IRBucketOffset: Params!$C$21
Name IRCorrBucket12: Params!$C$18
Name IRCorrBucket13: Params!$C$20
Name IRCorrBucket23: Params!$C$19
Name LambdaThresholdCO: Params!$C$24
Name LambdaThresholdIR: Params!$C$23
Name MinMaturityBD: Params!$C$11
Name MPORFloorBilateral: Params!$C$13
Name MPORFloorCleared: Params!$C$14
Name MPORFloorLarge: Params!$C$15
Name MultiplierFloor: Params!$C$8
Name Regime: Params!$C$22
Name ReportingCcy: Params!$C$6
Name SDFloorBD: Params!$C$12
Name SF_Table: Params!$A$27:$I$53
Name VolatilityFactor: Params!$C$17

Sheet README
B1: SA-CCR Calculator
B2: Standardised approach for counterparty credit risk - common Basel CRE52 core with an EU CRR (Art. 274-280f) rules layer. VBA engine v1.1.0.
B5: How to use
B6: 1. Enable macros | C6: Open the .xlsm, click "Enable Content". If Excel shows "Microsoft has blocked macros", close the file, right-click it > Properties > tick "Unblock", reopen.
B7: 2. Parameters | C7: Params: reporting date, reporting currency, default Regime (CRR or BCBS), regulatory constants, supervisory table and FX rates (units of reporting currency per 1 unit). Yellow cells are inputs.
B8: 3. Netting sets | C8: NettingSets: one row per netting set - margin agreement flags, MPOR drivers, collateral (net VM held, NICA), threshold, MTA and an optional Regime override. Collateral is entered after haircuts, in reporting currency.
B9: 4. Trades | C9: Trades: one row per derivative. Dropdowns guide the classification. Amounts can be in any currency of the FX table.
B10: 5. Run | C10: Click "Run SA-CCR" (macro RunSACCR). Results, HedgingSets, Buckets, TradeCalc and Checks are rebuilt. "Validate inputs" only runs the checks.
B11: 6. Review | C11: Checks lists every excluded trade and warning. TestCatalogue compares the engine with published / hand-calculated reference values per regime; Tests unit-tests the formula functions.
B12: 7. Regime | C12: Basel_vs_CRR lists every difference between CRE52 and the CRR, the source check status and how the workbook treats it. Regime-dependent rules are switched per netting set.
B14: Sign and input conventions
B15: Direction | C15: Long / Short in the primary risk factor. IR: Long = pay fixed (gains when rates rise). FX: Long = long the first currency of the pair. CR: Long = protection bought (as in the BCBS examples). EQ / CO: Long = long the underlying. Options: Long = bought.
B16: Sub-class | C16: IR, FX, OT: leave blank. CR: AAA ... CCC or CQS1 ... CQS6, IG_INDEX, SG_INDEX. EQ: SINGLE, INDEX. CO: ELECTRICITY, OIL_GAS, METALS, AGRICULTURAL, OTHER, CLIMATIC (CRR only). Asset class + "_" + sub-class must exist in the supervisory table; column "Regimes" restricts a row.
B17: Risk factor | C17: IR: currency (hedging set); inflation as the currency followed by -INFL, e.g. EUR-INFL, in its own hedging set [Art. 277(4)(a), 277a(1)]. FX: currency pair, e.g. EUR/USD (order is normalised and the sign adjusted). CR / EQ: reference entity or index name. CO: commodity type (trades with the same text are netted as one type). OT (CRR other risks): primary risk driver.
B18: Notional | C18: Positive amount; the sign comes from Direction. IR / CR: trade notional. FX: foreign-currency leg converted to reporting ccy. EQ / CO: market price x units.
B19: Dates | C19: Start (S, IR/CR only, blank = already started), End (E, IR/CR, also defines the IR maturity bucket), Maturity (M, maturity factor; defaults to End, then Expiry), Option expiry (T, options). Year fractions = days / DaysPerYear.
B20: Nature | C20: Standard, Basis (own hedging set per label, SF x 0.5, CRE52.46) or Volatility (own hedging set per label, SF x 5, CRE52.47).
B21: Options | C21: Underlying price P, strike K, supervisory vol from the table. Lambda: under CRR computed for IR and commodity options (Del. Reg. 2021/931 Art. 5); under BCBS taken from the trade (CRE52.40 FAQ). CDO: attachment A and detachment D as decimals.
B23: Methodology (per netting set)
B24: EAD | C24: EAD = alpha x (RC + PFE) [CRE52.1 / Art. 274(2)]; margined EAD capped at the unmargined EAD, with C = NICA only in both regimes [CRE52.2, CRE52.10; Art. 274(3), EBA Q&A 2023_6962]
B25: RC | C25: Unmargined: max(V - C, 0) [CRE52.10] Margined: max(V - C, TH + MTA - NICA, 0) [CRE52.18] C = VM + NICA
B26: PFE | C26: PFE = multiplier x AddOn; multiplier = min(1, 5% + 95% x exp((V - C) / (2 x 95% x AddOn))) [CRE52.23]
B27: Trade level | C27: Effective notional = delta x d x MF. d = notional x SD for IR/CR, SD = (e^-0.05S - e^-0.05E)/0.05, floored at 10 BD [CRE52.34]
B28: Maturity factor | C28: Unmargined: sqrt(min(max(M, 10 BD), 1y)) [CRE52.48]; margined: 1.5 x sqrt(MPOR/250) [CRE52.52]
B29: MPOR | C29: Floor 10 BD bilateral, 20 BD if > 5,000 trades or illiquid collateral, 5 BD (configurable) for client clearing: the clearing member in both regimes, the client under CRR only [CRE54.12; Art. 279c(1)]; + (N - 1) for remargining every N days; the result doubled for disputes [CRE52.50-52.52; Art. 285]
B30: IR | C30: Hedging set per currency; buckets <1y, 1-5y, >5y on E; EN = sqrt(D1^2+D2^2+D3^2+1.4D1D2+1.4D2D3+0.6D1D3); AddOn = 0.5% x EN [CRE52.57, Art. 280a]. BCBS only: IRBucketOffset = FALSE uses the sum of absolute bucket values [CRE52.57(5)]; a CRR netting set with IR trades is then INVALID.
B31: FX | C31: Hedging set per currency pair; AddOn = 4% x |sum effective notional| [CRE52.59]
B32: CR / EQ | C32: Entity add-on = SF x EN; AddOn = sqrt((sum rho x A)^2 + sum (1-rho^2) x A^2) [CRE52.61, 52.66]
B33: CO | C33: Hedging sets Energy (oil/gas + electricity), Metals, Agricultural, Other (+ Climatic under CRR); single-factor formula, rho = 40% [CRE52.70, Art. 277a]
B34: OT (CRR) | C34: Other risks: per hedging set AddOn = 8% x |sum effective notional| [Art. 280f]
B36: Sheets
B37: Params | C37: Inputs - parameters, supervisory factors, FX rates
B38: NettingSets | C38: Inputs - netting sets and margin terms
B39: Trades | C39: Inputs - trade population
B40: Results | C40: Output - EAD per netting set and total
B41: HedgingSets | C41: Output - hedging-set effective notionals and add-ons
B42: Buckets | C42: Output - IR maturity buckets, FX pairs, credit/equity entities, commodity types
B43: TradeCalc | C43: Output - every trade-level intermediate (S, E, M, T, SD, d, delta, MF, effective notional)
B44: Checks | C44: Output - validation errors (trade excluded) and warnings
B45: TestCatalogue | C45: Regression - reference tests with source, regime, expected value and tolerance
...

Sheet Params
A1: Parameters
A2: Codes in column A are read by the engine; only the yellow values are meant to be changed.
A4: Code | B4: Description | C4: Value | D4: Reference
A5: AsOfDate | B5: Reporting (calculation) date | C5: 46295
A6: ReportingCcy | B6: Reporting currency (all amounts converted into it) | C6: EUR
A7: Alpha | B7: Alpha multiplier on (RC + PFE) | C7: 1.4 | D7: CRE52.1 / CRR Art. 274(2)
A8: MultiplierFloor | B8: Floor of the PFE multiplier | C8: 0.05 | D8: CRE52.23
A9: DaysPerYear | B9: Calendar days per year for S, E, M, T | C9: 365
A10: BusinessDaysPerYear | B10: Business days per year (MPOR, floors) | C10: 250 | D10: CRE52.48, 52.52
A11: MinMaturityBD | B11: Floor on M for the unmargined maturity factor (BD) | C11: 10 | D11: CRE52.48
A12: SDFloorBD | B12: Floor on the supervisory duration (BD, 0 = none) | C12: 10 | D12: CRE52.34 / CRR Art. 279b
A13: MPORFloorBilateral | B13: MPOR floor, bilateral daily-margined netting set (BD) | C13: 10 | D13: CRE52.50
A14: MPORFloorCleared | B14: MPOR floor, client clearing (BD) | C14: 5 | D14: CRE54 - configurable
A15: MPORFloorLarge | B15: MPOR floor, >5,000 trades or illiquid collateral (BD) | C15: 20 | D15: CRE52.50
A16: BasisFactor | B16: Supervisory factor multiplier for basis transactions | C16: 0.5 | D16: CRE52.46
A17: VolatilityFactor | B17: Supervisory factor multiplier for volatility transactions | C17: 5 | D17: CRE52.47
A18: IRCorrBucket12 | B18: IR correlation bucket 1-2 (cross term 2 x 0.7 = 1.4) | C18: 0.7 | D18: CRE52.57
A19: IRCorrBucket23 | B19: IR correlation bucket 2-3 (cross term 1.4) | C19: 0.7 | D19: CRE52.57
A20: IRCorrBucket13 | B20: IR correlation bucket 1-3 (cross term 0.6) | C20: 0.3 | D20: CRE52.57
A21: IRBucketOffset | B21: TRUE = bucket formula; FALSE = sum of absolute bucket values | C21: TRUE | D21: CRE52.57(5); CRR allows TRUE only (Art. 280a(3))
A22: Regime | B22: Default regime: CRR (EU) or BCBS (Basel CRE52); override per netting set | C22: CRR | D22: see Basel_vs_CRR sheet | E22: CRR = EU regime; BCBS = Basel CRE52
A23: LambdaThresholdIR | B23: CRR lambda threshold, IR options (shift = max(thr - min(P,K), 0)) | C23: 0.001 | D23: Del. Reg. 2021/931 Art. 5 (am. 2025/855)
A24: LambdaThresholdCO | B24: CRR lambda threshold, commodity options (shift = max(-(1+thr) min(P,K), 0)) | C24: 0.1 | D24: Del. Reg. 2021/931 Art. 5 (am. 2025/855)
A26: Supervisory parameters (CRE52.72 / CRR Art. 279a, 280a-280f)
A27: SF_Key | B27: Asset class | C27: Category | D27: Supervisory factor | E27: Correlation | F27: Supervisory option vol | G27: Commodity hedging set | H27: Regimes | I27: Reference
A28: IR | B28: IR | D28: 0.005 | F28: 0.5 | H28: BOTH | I28: CRE52.72 / CRR Art. 280a
A29: FX | B29: FX | D29: 0.04 | F29: 0.15 | H29: BOTH | I29: CRE52.72 / CRR Art. 280b
A30: CR_AAA | B30: CR | C30: AAA | D30: 0.0038 | E30: 0.5 | F30: 1 | H30: BOTH | I30: CRE52.72
A31: CR_AA | B31: CR | C31: AA | D31: 0.0038 | E31: 0.5 | F31: 1 | H31: BOTH | I31: CRE52.72
A32: CR_A | B32: CR | C32: A | D32: 0.0042 | E32: 0.5 | F32: 1 | H32: BOTH | I32: CRE52.72
A33: CR_BBB | B33: CR | C33: BBB | D33: 0.0054 | E33: 0.5 | F33: 1 | H33: BOTH | I33: CRE52.72
A34: CR_BB | B34: CR | C34: BB | D34: 0.0106 | E34: 0.5 | F34: 1 | H34: BOTH | I34: CRE52.72
A35: CR_B | B35: CR | C35: B | D35: 0.016 | E35: 0.5 | F35: 1 | H35: BOTH | I35: CRE52.72
A36: CR_CCC | B36: CR | C36: CCC | D36: 0.06 | E36: 0.5 | F36: 1 | H36: BOTH | I36: CRE52.72
A37: CR_CQS1 | B37: CR | C37: CQS1 | D37: 0.0038 | E37: 0.5 | F37: 1 | H37: BOTH | I37: CRR Art. 280c Table 3
A38: CR_CQS2 | B38: CR | C38: CQS2 | D38: 0.0042 | E38: 0.5 | F38: 1 | H38: BOTH | I38: CRR Art. 280c Table 3
A39: CR_CQS3 | B39: CR | C39: CQS3 | D39: 0.0054 | E39: 0.5 | F39: 1 | H39: BOTH | I39: CRR Art. 280c Table 3
A40: CR_CQS4 | B40: CR | C40: CQS4 | D40: 0.0106 | E40: 0.5 | F40: 1 | H40: BOTH | I40: CRR Art. 280c Table 3
A41: CR_CQS5 | B41: CR | C41: CQS5 | D41: 0.016 | E41: 0.5 | F41: 1 | H41: BOTH | I41: CRR Art. 280c Table 3
... A46: EQ_INDEX | B46: EQ | C46: INDEX | D46: 0.2 | E46: 0.8 | F46: 0.75 | H46: BOTH | I46: CRE52.72 / CRR Art. 280d
...

Sheet NettingSets
A1: Netting sets
A2: One row per legally enforceable netting set. Collateral after haircuts, reporting currency; VM / NICA positive = held, negative = posted. Client clearing role: N, CM (the bank is the clearing member) or CLIENT. Margin agreements: blank for one agreement, or none, covering only this netting set; MIXED or SHARED declares a structure the engine rejects.
A4: NettingSetID | B4: Counterparty | C4: Margined (Y/N) | D4: Client clearing role (N/CM/CLIENT) | E4: Remargin frequency N (BD) | F4: >5,000 trades or illiquid collateral (Y/N) | G4: Margin disputes (Y/N) | H4: MPOR override (BD) | I4: Net VM held (+) / posted (-) | J4: NICA | K4: Threshold TH | L4: MTA | M4: Alpha override | N4: Regime override (blank = Params) | O4: Margin agreements (blank/MIXED/SHARED)
A5: BCBS-EX1 | B5: CRE99 / BCBS 279 Annex 4 - example 1 (IR) | C5: N | D5: N | F5: N | G5: N | I5: 0 | J5: 0 | K5: 0 | L5: 0 | N5: BCBS
A6: BCBS-EX2 | B6: CRE99 / BCBS 279 Annex 4 - example 2 (credit) | C6: N | D6: N | F6: N | G6: N | I6: 0 | J6: 0 | K6: 0 | L6: 0 | N6: BCBS
A7: BCBS-EX3 | B7: CRE99 / BCBS 279 Annex 4 - example 3 (commodity) | C7: N | D7: N | F7: N | G7: N | I7: 0 | J7: 0 | K7: 0 | L7: 0 | N7: BCBS
A8: BCBS-EX4 | B8: CRE99 / BCBS 279 Annex 4 - example 4 (IR + credit) | C8: N | D8: N | F8: N | G8: N | I8: 0 | J8: 0 | K8: 0 | L8: 0 | N8: BCBS
A9: BCBS-EX5 | B9: CRE99 / BCBS 279 Annex 4 - example 5 (IR + commodity, weekly margin) | C9: Y | D9: N | E9: 5 | F9: N | G9: N | I9: 50 | J9: 150 | K9: 0 | L9: 5 | N9: BCBS
A10: CRR-EX5 | B10: Example 5 inputs under CRR (cap not binding: same EAD) | C10: Y | D10: N | E10: 5 | F10: N | G10: N | I10: 50 | J10: 150 | K10: 0 | L10: 5 | N10: CRR
A11: BCBS-VMCAP | B11: Posted-VM scenario after EBA Q&A 2022_6354 - Basel cap | C11: Y | D11: N | E11: 1 | F11: N | G11: N | I11: -1300000000 | J11: 0 | K11: 0 | L11: 0 | N11: BCBS
A12: CRR-VMCAP | B12: Posted-VM scenario after EBA Q&A 2022_6354 - CRR Art. 274(3) cap | C12: Y | D12: N | E12: 1 | F12: N | G12: N | I12: -1300000000 | J12: 0 | K12: 0 | L12: 0 | N12: CRR
A13: CRR-EX1-1PCT | B13: Example 1 with swaption forward at 1% (EBA RTS scenario) | C13: N | D13: N | F13: N | G13: N | I13: 0 | J13: 0 | K13: 0 | L13: 0 | N13: CRR
A14: CRR-NEGIR | B14: Receiver swaption, negative forward rate - RTS lambda | C14: N | D14: N | F14: N | G14: N | I14: 0 | J14: 0 | K14: 0 | L14: 0 | N14: CRR
A15: BCBS-NEGIR | B15: Same swaption under BCBS without lambda - must be rejected | C15: N | D15: N | F15: N | G15: N | I15: 0 | J15: 0 | K15: 0 | L15: 0 | N15: BCBS
A16: CRR-NEGCO | B16: Commodity call, negative price and strike - RTS lambda | C16: N | D16: N | F16: N | G16: N | I16: 0 | J16: 0 | K16: 0 | L16: 0 | N16: CRR
A17: CRR-OTHER | B17: Other risks category (Art. 280f) - hand-checkable | C17: N | D17: N | F17: N | G17: N | I17: 0 | J17: 0 | K17: 0 | L17: 0 | N17: CRR
A18: CRR-CLIMATE | B18: Climatic-conditions hedging set (Art. 277a) - SF to confirm | C18: N | D18: N | F18: N | G18: N | I18: 0 | J18: 0 | K18: 0 | L18: 0 | N18: CRR
A19: NS-ALPHA | B19: Alpha Bank plc (no CSA) | C19: N | D19: N | F19: N | G19: N | I19: 0 | J19: 0 | K19: 0 | L19: 0
A20: NS-GAMMA | B20: Gamma Fund Ltd (daily CSA + IM) | C20: Y | D20: N | E20: 1 | F20: N | G20: N | I20: 1500000 | J20: 2000000 | K20: 0 | L20: 250000
A21: DEMO-REJECTED | B21: Deliberately rejected trades (demo): OT-X is other risks under BCBS, A11 has matured | C21: N | D21: N | F21: N | G21: N | I21: 0 | J21: 0 | K21: 0 | L21: 0 | N21: BCBS

Sheet Trades
A1: Trades
A2: One row per trade, from row 5. Blank TradeID = row ignored.
A3: unique | B3: must exist on NettingSets | C3: IR FX CR EQ CO OT | D3: blank for IR/FX/OT; see README | E3: IR: ccy; FX: pair; CR/EQ: name; CO: type | F3: Linear / Option / CDO | G3: Long / Short | H3: Call / Put | I3: Standard / Basis / Volatility | J3: basis & vol only | K3: positive | M3: signed | N3: default = notional ccy | O3: IR/CR; blank = started | P3: IR/CR | Q3: default = end | R3: options | S3: options | T3: options | U3: BCBS only | V3: CDO | W3: CDO
A4: TradeID | B4: NettingSetID | C4: Asset class | D4: Sub-class | E4: Risk factor / reference | F4: Instrument | G4: Direction | H4: Option type | I4: Nature | J4: Basis / vol hedging-set label | K4: Notional | L4: Notional ccy | M4: MtM | N4: MtM ccy | O4: Start date (S) | P4: End date (E) | Q4: Maturity date (M) | R4: Option expiry (T) | S4: Underlying price P | T4: Strike K | U4: Lambda shift | V4: Attachment A | W4: Detachment D | X4: Comment
A5: EX1-T1 | B5: BCBS-EX1 | C5: IR | E5: USD | F5: Linear | G5: Long | I5: Standard | K5: 10000 | L5: EUR | M5: 30 | N5: EUR | P5: 49945 | Q5: 49945 | X5: 10y IRS pay fixed - Basel ex.1 trade 1
A6: EX1-T2 | B6: BCBS-EX1 | C6: IR | E6: USD | F6: Linear | G6: Short | I6: Standard | K6: 10000 | L6: EUR | M6: -20 | N6: EUR | P6: 47755 | Q6: 47755 | X6: 4y IRS receive fixed - Basel ex.1 trade 2
A7: EX1-T3 | B7: BCBS-EX1 | C7: IR | E7: EUR | F7: Option | G7: Long | H7: Put | I7: Standard | K7: 5000 | L7: EUR | M7: 50 | N7: EUR | O7: 46660 | P7: 50310 | Q7: 50310 | R7: 46660 | S7: 0.06 | T7: 0.05 | X7: Bought 1y-into-10y receiver swaption - Basel ex.1 trade 3
A8: EX2-T1 | B8: BCBS-EX2 | C8: CR | D8: AA | E8: FIRM A | F8: Linear | G8: Long | I8: Standard | K8: 10000 | L8: EUR | M8: 20 | N8: EUR | P8: 47390 | Q8: 47390 | X8: 3y CDS protection bought
A9: EX2-T2 | B9: BCBS-EX2 | C9: CR | D9: BBB | E9: FIRM B | F9: Linear | G9: Short | I9: Standard | K9: 10000 | L9: EUR | M9: -40 | N9: EUR | P9: 48485 | Q9: 48485 | X9: 6y CDS protection sold
A10: EX2-T3 | B10: BCBS-EX2 | C10: CR | D10: IG_INDEX | E10: CDX.IG | F10: Linear | G10: Long | I10: Standard | K10: 10000 | L10: EUR | M10: 0 | N10: EUR | P10: 48120 | Q10: 48120 | X10: 5y index CDS protection bought
A11: EX3-T1 | B11: BCBS-EX3 | C11: CO | D11: OIL_GAS | E11: CRUDE OIL | F11: Linear | G11: Long | I11: Standard | K11: 10000 | L11: EUR | M11: -50 | N11: EUR | Q11: 46569 | X11: 9m WTI forward (Basel treats WTI and Brent as one type)
A12: EX3-T2 | B12: BCBS-EX3 | C12: CO | D12: OIL_GAS | E12: CRUDE OIL | F12: Linear | G12: Short | I12: Standard | K12: 20000 | L12: EUR | M12: -30 | N12: EUR | Q12: 47025 | X12: 2y Brent forward
A13: EX3-T3 | B13: BCBS-EX3 | C13: CO | D13: METALS | E13: SILVER | F13: Linear | G13: Long | I13: Standard | K13: 10000 | L13: EUR | M13: 100 | N13: EUR | Q13: 48120 | X13: 5y silver forward
A14: EX4-IRT1 | B14: BCBS-EX4 | C14: IR | E14: USD | F14: Linear | G14: Long | I14: Standard | K14: 10000 | L14: EUR | M14: 30 | N14: EUR | P14: 49945 | Q14: 49945 | X14: 10y IRS pay fixed - Basel ex.1 trade 1
A15: EX4-IRT2 | B15: BCBS-EX4 | C15: IR | E15: USD | F15: Linear | G15: Short | I15: Standard | K15: 10000 | L15: EUR | M15: -20 | N15: EUR | P15: 47755 | Q15: 47755 | X15: 4y IRS receive fixed - Basel ex.1 trade 2
A16: EX4-IRT3 | B16: BCBS-EX4 | C16: IR | E16: EUR | F16: Option | G16: Long | H16: Put | I16: Standard | K16: 5000 | L16: EUR | M16: 50 | N16: EUR | O16: 46660 | P16: 50310 | Q16: 50310 | R16: 46660 | S16: 0.06 | T16: 0.05 | X16: Bought 1y-into-10y receiver swaption - Basel ex.1 trade 3
A17: EX4-CRT1 | B17: BCBS-EX4 | C17: CR | D17: AA | E17: FIRM A | F17: Linear | G17: Long | I17: Standard | K17: 10000 | L17: EUR | M17: 20 | N17: EUR | P17: 47390 | Q17: 47390 | X17: 3y CDS protection bought
A18: EX4-CRT2 | B18: BCBS-EX4 | C18: CR | D18: BBB | E18: FIRM B | F18: Linear | G18: Short | I18: Standard | K18: 10000 | L18: EUR | M18: -40 | N18: EUR | P18: 48485 | Q18: 48485 | X18: 6y CDS protection sold
A19: EX4-CRT3 | B19: BCBS-EX4 | C19: CR | D19: IG_INDEX | E19: CDX.IG | F19: Linear | G19: Long | I19: Standard | K19: 10000 | L19: EUR | M19: 0 | N19: EUR | P19: 48120 | Q19: 48120 | X19: 5y index CDS protection bought
A20: EX5-IRT1 | B20: BCBS-EX5 | C20: IR | E20: USD | F20: Linear | G20: Long | I20: Standard | K20: 10000 | L20: EUR | M20: 30 | N20: EUR | P20: 49945 | Q20: 49945 | X20: 10y IRS pay fixed - Basel ex.1 trade 1
A21: EX5-IRT2 | B21: BCBS-EX5 | C21: IR | E21: USD | F21: Linear | G21: Short | I21: Standard | K21: 10000 | L21: EUR | M21: -20 | N21: EUR | P21: 47755 | Q21: 47755 | X21: 4y IRS receive fixed - Basel ex.1 trade 2
A22: EX5-IRT3 | B22: BCBS-EX5 | C22: IR | E22: EUR | F22: Option | G22: Long | H22: Put | I22: Standard | K22: 5000 | L22: EUR | M22: 50 | N22: EUR | O22: 46660 | P22: 50310 | Q22: 50310 | R22: 46660 | S22: 0.06 | T22: 0.05 | X22: Bought 1y-into-10y receiver swaption - Basel ex.1 trade 3
A23: EX5-COT1 | B23: BCBS-EX5 | C23: CO | D23: OIL_GAS | E23: CRUDE OIL | F23: Linear | G23: Long | I23: Standard | K23: 10000 | L23: EUR | M23: -50 | N23: EUR | Q23: 46569 | X23: 9m WTI forward (Basel treats WTI and Brent as one type)
A24: EX5-COT2 | B24: BCBS-EX5 | C24: CO | D24: OIL_GAS | E24: CRUDE OIL | F24: Linear | G24: Short | I24: Standard | K24: 20000 | L24: EUR | M24: -30 | N24: EUR | Q24: 47025 | X24: 2y Brent forward
A25: EX5-COT3 | B25: BCBS-EX5 | C25: CO | D25: METALS | E25: SILVER | F25: Linear | G25: Long | I25: Standard | K25: 10000 | L25: EUR | M25: 100 | N25: EUR | Q25: 48120 | X25: 5y silver forward
A26: EU5-IRT1 | B26: CRR-EX5 | C26: IR | E26: USD | F26: Linear | G26: Long | I26: Standard | K26: 10000 | L26: EUR | M26: 30 | N26: EUR | P26: 49945 | Q26: 49945 | X26: 10y IRS pay fixed - Basel ex.1 trade 1
A27: EU5-IRT2 | B27: CRR-EX5 | C27: IR | E27: USD | F27: Linear | G27: Short | I27: Standard | K27: 10000 | L27: EUR | M27: -20 | N27: EUR | P27: 47755 | Q27: 47755 | X27: 4y IRS receive fixed - Basel ex.1 trade 2
A28: EU5-IRT3 | B28: CRR-EX5 | C28: IR | E28: EUR | F28: Option | G28: Long | H28: Put | I28: Standard | K28: 5000 | L28: EUR | M28: 50 | N28: EUR | O28: 46660 | P28: 50310 | Q28: 50310 | R28: 46660 | S28: 0.06 | T28: 0.05 | X28: Bought 1y-into-10y receiver swaption - Basel ex.1 trade 3
A29: EU5-COT1 | B29: CRR-EX5 | C29: CO | D29: OIL_GAS | E29: CRUDE OIL | F29: Linear | G29: Long | I29: Standard | K29: 10000 | L29: EUR | M29: -50 | N29: EUR | Q29: 46569 | X29: 9m WTI forward (Basel treats WTI and Brent as one type)
A30: EU5-COT2 | B30: CRR-EX5 | C30: CO | D30: OIL_GAS | E30: CRUDE OIL | F30: Linear | G30: Short | I30: Standard | K30: 20000 | L30: EUR | M30: -30 | N30: EUR | Q30: 47025 | X30: 2y Brent forward
A31: EU5-COT3 | B31: CRR-EX5 | C31: CO | D31: METALS | E31: SILVER | F31: Linear | G31: Long | I31: Standard | K31: 10000 | L31: EUR | M31: 100 | N31: EUR | Q31: 48120 | X31: 5y silver forward
A32: EU1P-T1 | B32: CRR-EX1-1PCT | C32: IR | E32: USD | F32: Linear | G32: Long | I32: Standard | K32: 10000 | L32: EUR | M32: 30 | N32: EUR | P32: 49945 | Q32: 49945 | X32: 10y IRS pay fixed - Basel ex.1 trade 1
A33: EU1P-T2 | B33: CRR-EX1-1PCT | C33: IR | E33: USD | F33: Linear | G33: Short | I33: Standard | K33: 10000 | L33: EUR | M33: -20 | N33: EUR | P33: 47755 | Q33: 47755 | X33: 4y IRS receive fixed - Basel ex.1 trade 2
A34: EU1P-T3 | B34: CRR-EX1-1PCT | C34: IR | E34: EUR | F34: Option | G34: Long | H34: Put | I34: Standard | K34: 5000 | L34: EUR | M34: 50 | N34: EUR | O34: 46660 | P34: 50310 | Q34: 50310 | R34: 46660 | S34: 0.01 | T34: 0.05 | X34: Swaption with forward 1% (strike 5%)
A35: VMB-1 | B35: BCBS-VMCAP | C35: IR | E35: EUR | F35: Linear | G35: Short | I35: Standard | K35: 5845000000 | L35: EUR | M35: -1100000000 | N35: EUR | P35: 49945 | Q35: 49945 | X35: 10y IRS, MtM -1.1bn, VM posted 1.3bn
A36: VMC-1 | B36: CRR-VMCAP | C36: IR | E36: EUR | F36: Linear | G36: Short | I36: Standard | K36: 5845000000 | L36: EUR | M36: -1100000000 | N36: EUR | P36: 49945 | Q36: 49945 | X36: 10y IRS, MtM -1.1bn, VM posted 1.3bn
A37: NIR-C | B37: CRR-NEGIR | C37: IR | E37: EUR | F37: Option | G37: Long | H37: Put | I37: Standard | K37: 10000 | L37: EUR | M37: 15 | N37: EUR | O37: 46660 | P37: 48485 | Q37: 48485 | R37: 46660 | S37: -0.002 | T37: 0.001 | X37: CRR: lambda = 0.10% - (-0.20%) = 0.30%; BCBS: no lambda entered -> rejected
A38: NIR-B | B38: BCBS-NEGIR | C38: IR | E38: EUR | F38: Option | G38: Long | H38: Put | I38: Standard | K38: 10000 | L38: EUR | M38: 15 | N38: EUR | O38: 46660 | P38: 48485 | Q38: 48485 | R38: 46660 | S38: -0.002 | T38: 0.001 | X38: CRR: lambda = 0.10% - (-0.20%) = 0.30%; BCBS: no lambda entered -> rejected
A39: NCO-1 | B39: CRR-NEGCO | C39: CO | D39: OIL_GAS | E39: WTI | F39: Option | G39: Long | H39: Call | I39: Standard | K39: 10000 | L39: EUR | M39: 40 | N39: EUR | Q39: 46477 | R39: 46477 | S39: -5 | T39: -4 | X39: lambda = -(1+0.1) x (-5) = 5.5
A40: OT-1 | B40: CRR-OTHER | C40: OT | E40: LONGEVITY INDEX X | F40: Linear | G40: Long | I40: Standard | K40: 10000 | L40: EUR | M40: 0 | N40: EUR | Q40: 47025 | X40: Longevity swap - other risks category
...

Sheet Results
A1: SA-CCR results
A2: No results yet: build the workbook from the source, then press Run SA-CCR.
A3: {=ResultsStatusText(SACCR_RunInputs,NettingSets!$A:$O,Trades!$A:$W,Params!$A:$H)} -> No results: press Run SA-CCR.
A4: NettingSetID | B4: Counterparty | C4: Regime | D4: Margined | E4: Trades | F4: MPOR (BD) | G4: V (sum MtM) | H4: C (VM + NICA) | I4: RC | J4: AddOn IR | K4: AddOn FX | L4: AddOn CR | M4: AddOn EQ | N4: AddOn CO | O4: AddOn OT | P4: AddOn aggregate | Q4: Multiplier | R4: PFE | S4: Alpha | T4: EAD margined | U4: EAD cap (unmargined) | V4: EAD | W4: Cap applied | X4: C (cap basis) | Y4: RC (cap basis) | Z4: AddOn unmargined | AA4: Multiplier (cap basis) | AB4: Status

Sheet HedgingSets
A1: Hedging sets
A2: Margined netting sets are shown with the margined maturity factor; column L always shows the unmargined add-on used for the EAD cap.
A4: NettingSetID | B4: Asset class | C4: Hedging set | D4: Trades | E4: D1 (<1y) | F4: D2 (1-5y) | G4: D3 (>5y) | H4: Effective notional (IR / FX / OT) | I4: Systematic: sum rho x A | J4: Idiosyncratic: sqrt(sum (1-rho^2) A^2) | K4: Hedging-set add-on | L4: Add-on unmargined | M4: Basis | N4: SF (IR / FX / OT)

Sheet Buckets
A1: Buckets, entities and commodity types
A2: IR: maturity bucket <1Y / 1-5Y / >5Y on E. FX: currency pair. CR / EQ: reference entity. CO: commodity type.
A4: NettingSetID | B4: Asset class | C4: Hedging set | D4: Bucket / entity / type | E4: Trades | F4: SF | G4: Correlation | H4: Effective notional unmargined | I4: Effective notional margined | J4: Entity / type add-on unmargined | K4: Entity / type add-on margined

Sheet TradeCalc
A1: Trade-level calculation
A2: Every intermediate of the trade-level SA-CCR formula; excluded trades show the reason in Messages.
A4: TradeID | B4: NettingSetID | C4: Asset class | D4: Status | E4: Hedging set | F4: Bucket / entity / type | G4: SF (effective) | H4: Notional (rep ccy) | I4: MtM (rep ccy) | J4: S | K4: E | L4: M | M4: T (option) | N4: Supervisory duration | O4: Adjusted notional d | P4: Supervisory delta | Q4: MF unmargined | R4: MF margined | S4: Effective notional unmargined | T4: Effective notional margined | U4: IR bucket | V4: Stand-alone add-on | W4: Lambda | X4: Regime | Y4: Messages

Sheet Checks
A1: Checks
A2: Errors exclude the trade from the calculation; warnings do not.
A4: Severity | B4: Sheet | C4: Row | D4: Reference | E4: Message

Sheet TestCatalogue
A1: Reference-test catalogue
A2: Each test reads one output cell by netting set / trade ID and column header. Basel and EU expectations are kept separate even where they coincide. Values shown are from the last run.
A4: Test | B4: Area | C4: Description | D4: Source | E4: Source status | F4: Regime | G4: Sheet | H4: Reference | I4: Metric | J4: Expected | K4: Tolerance type | L4: Tolerance | M4: Engine | N4: Difference | O4: Result | P4: Note
A5: T01 | B5: Core - IR | C5: Example 1: adjusted notional, 10y swap | D5: CRE99 ex.1 / BCBS 279 Annex 4 | E5: Official published value (rounded) | F5: BCBS | G5: TradeCalc | H5: EX1-T1 | I5: Adjusted notional d | J5: 78694 | K5: abs | L5: 0.5 | M5: =IFERROR(INDEX(TradeCalc!$A$5:$Y$3000,MATCH($H5,TradeCalc!$A$5:$A$3000,0),MATCH($I5,TradeCalc!$A$4:$Y$4,0)),"n/a") -> 78693.868 | N5: =IF(AND(ISNUMBER(M5),ISNUMBER(J5)),M5-J5,"") -> -0.13194253 | O5: =IF(K5="text",IF(M5&""=J5&"","PASS","FAIL"),IF(NOT(ISNUMBER(M5)),"FAIL",IF(K5="rel",IF(ABS(N5)<=L5*MAX(1,ABS(J5)),"PASS","FAIL"),IF(ABS(N5)<=L5,"PASS","FAIL")))) -> PASS
A6: T02 | B6: Core - IR | C6: Example 1: supervisory delta, swaption | D6: CRE99 ex.1 | E6: Official published value (rounded) | F6: BCBS | G6: TradeCalc | H6: EX1-T3 | I6: Supervisory delta | J6: -0.27 | K6: abs | L6: 0.005 | M6: =IFERROR(INDEX(TradeCalc!$A$5:$Y$3000,MATCH($H6,TradeCalc!$A$5:$A$3000,0),MATCH($I6,TradeCalc!$A$4:$Y$4,0)),"n/a") -> -0.26939522 | N6: =IF(AND(ISNUMBER(M6),ISNUMBER(J6)),M6-J6,"") -> 0.00060478229 | O6: =IF(K6="text",IF(M6&""=J6&"","PASS","FAIL"),IF(NOT(ISNUMBER(M6)),"FAIL",IF(K6="rel",IF(ABS(N6)<=L6*MAX(1,ABS(J6)),"PASS","FAIL"),IF(ABS(N6)<=L6,"PASS","FAIL")))) -> PASS
A7: T03 | B7: Core - IR | C7: Example 1: IR add-on | D7: CRE99 ex.1 | E7: Official published value (rounded) | F7: BCBS | G7: Results | H7: BCBS-EX1 | I7: AddOn IR | J7: 347 | K7: abs | L7: 0.5 | M7: =IFERROR(INDEX(Results!$A$5:$AA$3000,MATCH($H7,Results!$A$5:$A$3000,0),MATCH($I7,Results!$A$4:$AA$4,0)),"n/a") -> 346.76439 | N7: =IF(AND(ISNUMBER(M7),ISNUMBER(J7)),M7-J7,"") -> -0.23561362 | O7: =IF(K7="text",IF(M7&""=J7&"","PASS","FAIL"),IF(NOT(ISNUMBER(M7)),"FAIL",IF(K7="rel",IF(ABS(N7)<=L7*MAX(1,ABS(J7)),"PASS","FAIL"),IF(ABS(N7)<=L7,"PASS","FAIL")))) -> PASS
A8: T04 | B8: Core - IR | C8: Example 1: EAD | D8: CRE99 ex.1 | E8: Official published value (rounded) | F8: BCBS | G8: Results | H8: BCBS-EX1 | I8: EAD | J8: 569 | K8: abs | L8: 0.5 | M8: =IFERROR(INDEX(Results!$A$5:$AA$3000,MATCH($H8,Results!$A$5:$A$3000,0),MATCH($I8,Results!$A$4:$AA$4,0)),"n/a") -> 569.47014 | N8: =IF(AND(ISNUMBER(M8),ISNUMBER(J8)),M8-J8,"") -> 0.47014094 | O8: =IF(K8="text",IF(M8&""=J8&"","PASS","FAIL"),IF(NOT(ISNUMBER(M8)),"FAIL",IF(K8="rel",IF(ABS(N8)<=L8*MAX(1,ABS(J8)),"PASS","FAIL"),IF(ABS(N8)<=L8,"PASS","FAIL")))) -> PASS
A9: T05 | B9: Core - credit | C9: Example 2: multiplier | D9: CRE99 ex.2 | E9: Official published value (rounded) | F9: BCBS | G9: Results | H9: BCBS-EX2 | I9: Multiplier | J9: 0.965 | K9: abs | L9: 0.0005 | M9: =IFERROR(INDEX(Results!$A$5:$AA$3000,MATCH($H9,Results!$A$5:$A$3000,0),MATCH($I9,Results!$A$4:$AA$4,0)),"n/a") -> 0.96520828 | N9: =IF(AND(ISNUMBER(M9),ISNUMBER(J9)),M9-J9,"") -> 0.000208281 | O9: =IF(K9="text",IF(M9&""=J9&"","PASS","FAIL"),IF(NOT(ISNUMBER(M9)),"FAIL",IF(K9="rel",IF(ABS(N9)<=L9*MAX(1,ABS(J9)),"PASS","FAIL"),IF(ABS(N9)<=L9,"PASS","FAIL")))) -> PASS
A10: T06 | B10: Core - credit | C10: Example 2: EAD | D10: CRE99 ex.2 | E10: Official published value (rounded) | F10: BCBS | G10: Results | H10: BCBS-EX2 | I10: EAD | J10: 381 | K10: abs | L10: 0.5 | M10: =IFERROR(INDEX(Results!$A$5:$AA$3000,MATCH($H10,Results!$A$5:$A$3000,0),MATCH($I10,Results!$A$4:$AA$4,0)),"n/a") -> 381.23832 | N10: =IF(AND(ISNUMBER(M10),ISNUMBER(J10)),M10-J10,"") -> 0.23831875 | O10: =IF(K10="text",IF(M10&""=J10&"","PASS","FAIL"),IF(NOT(ISNUMBER(M10)),"FAIL",IF(K10="rel",IF(ABS(N10)<=L10*MAX(1,ABS(J10)),"PASS","FAIL"),IF(ABS(N10)<=L10,"PASS","FAIL")))) -> PASS
A11: T07 | B11: Core - commodity | C11: Example 3: EAD | D11: CRE99 ex.3 | E11: Official published value (rounded) | F11: BCBS | G11: Results | H11: BCBS-EX3 | I11: EAD | J11: 5406 | K11: abs | L11: 2 | M11: =IFERROR(INDEX(Results!$A$5:$AA$3000,MATCH($H11,Results!$A$5:$A$3000,0),MATCH($I11,Results!$A$4:$AA$4,0)),"n/a") -> 5404.6197 | N11: =IF(AND(ISNUMBER(M11),ISNUMBER(J11)),M11-J11,"") -> -1.3803125 | O11: =IF(K11="text",IF(M11&""=J11&"","PASS","FAIL"),IF(NOT(ISNUMBER(M11)),"FAIL",IF(K11="rel",IF(ABS(N11)<=L11*MAX(1,ABS(J11)),"PASS","FAIL"),IF(ABS(N11)<=L11,"PASS","FAIL")))) -> PASS | P11: 9-month leg entered as 274 days (0.7507y vs 0.75y): ~1.4 below published
A12: T08 | B12: Core - aggregation | C12: Example 4: RC | D12: CRE99 ex.4 | E12: Official published value (rounded) | F12: BCBS | G12: Results | H12: BCBS-EX4 | I12: RC | J12: 40 | K12: abs | L12: 0.5 | M12: =IFERROR(INDEX(Results!$A$5:$AA$3000,MATCH($H12,Results!$A$5:$A$3000,0),MATCH($I12,Results!$A$4:$AA$4,0)),"n/a") -> 40 | N12: =IF(AND(ISNUMBER(M12),ISNUMBER(J12)),M12-J12,"") -> 0 | O12: =IF(K12="text",IF(M12&""=J12&"","PASS","FAIL"),IF(NOT(ISNUMBER(M12)),"FAIL",IF(K12="rel",IF(ABS(N12)<=L12*MAX(1,ABS(J12)),"PASS","FAIL"),IF(ABS(N12)<=L12,"PASS","FAIL")))) -> PASS
A13: T09 | B13: Core - aggregation | C13: Example 4: aggregate add-on (no diversification across classes) | D13: CRE99 ex.4 | E13: Official published value (rounded) | F13: BCBS | G13: Results | H13: BCBS-EX4 | I13: AddOn aggregate | J13: 629 | K13: abs | L13: 0.5 | M13: =IFERROR(INDEX(Results!$A$5:$AA$3000,MATCH($H13,Results!$A$5:$A$3000,0),MATCH($I13,Results!$A$4:$AA$4,0)),"n/a") -> 628.89322 | N13: =IF(AND(ISNUMBER(M13),ISNUMBER(J13)),M13-J13,"") -> -0.10678176 | O13: =IF(K13="text",IF(M13&""=J13&"","PASS","FAIL"),IF(NOT(ISNUMBER(M13)),"FAIL",IF(K13="rel",IF(ABS(N13)<=L13*MAX(1,ABS(J13)),"PASS","FAIL"),IF(ABS(N13)<=L13,"PASS","FAIL")))) -> PASS
A14: T10 | B14: Core - aggregation | C14: Example 4: EAD | D14: CRE99 ex.4 | E14: Official published value (rounded) | F14: BCBS | G14: Results | H14: BCBS-EX4 | I14: EAD | J14: 936 | K14: abs | L14: 0.6 | M14: =IFERROR(INDEX(Results!$A$5:$AA$3000,MATCH($H14,Results!$A$5:$A$3000,0),MATCH($I14,Results!$A$4:$AA$4,0)),"n/a") -> 936.45051 | N14: =IF(AND(ISNUMBER(M14),ISNUMBER(J14)),M14-J14,"") -> 0.45050554 | O14: =IF(K14="text",IF(M14&""=J14&"","PASS","FAIL"),IF(NOT(ISNUMBER(M14)),"FAIL",IF(K14="rel",IF(ABS(N14)<=L14*MAX(1,ABS(J14)),"PASS","FAIL"),IF(ABS(N14)<=L14,"PASS","FAIL")))) -> PASS | P14: Published 936 = 1.4 x (40 + 629) with rounded add-ons; unrounded 936.5
A15: T11 | B15: Core - margined | C15: Example 5: MPOR, weekly remargining | D15: CRE99 ex.5 | E15: Official published value (rounded) | F15: BCBS | G15: Results | H15: BCBS-EX5 | I15: MPOR (BD) | J15: 14 | K15: abs | L15: 0 | M15: =IFERROR(INDEX(Results!$A$5:$AA$3000,MATCH($H15,Results!$A$5:$A$3000,0),MATCH($I15,Results!$A$4:$AA$4,0)),"n/a") -> 14 | N15: =IF(AND(ISNUMBER(M15),ISNUMBER(J15)),M15-J15,"") -> 0 | O15: =IF(K15="text",IF(M15&""=J15&"","PASS","FAIL"),IF(NOT(ISNUMBER(M15)),"FAIL",IF(K15="rel",IF(ABS(N15)<=L15*MAX(1,ABS(J15)),"PASS","FAIL"),IF(ABS(N15)<=L15,"PASS","FAIL")))) -> PASS
A16: T12 | B16: Core - margined | C16: Example 5: aggregate add-on | D16: CRE99 ex.5 | E16: Official published value (rounded) | F16: BCBS | G16: Results | H16: BCBS-EX5 | I16: AddOn aggregate | J16: 1401 | K16: abs | L16: 0.5 | M16: =IFERROR(INDEX(Results!$A$5:$AA$3000,MATCH($H16,Results!$A$5:$A$3000,0),MATCH($I16,Results!$A$4:$AA$4,0)),"n/a") -> 1400.9624 | N16: =IF(AND(ISNUMBER(M16),ISNUMBER(J16)),M16-J16,"") -> -0.037620303 | O16: =IF(K16="text",IF(M16&""=J16&"","PASS","FAIL"),IF(NOT(ISNUMBER(M16)),"FAIL",IF(K16="rel",IF(ABS(N16)<=L16*MAX(1,ABS(J16)),"PASS","FAIL"),IF(ABS(N16)<=L16,"PASS","FAIL")))) -> PASS
A17: T13 | B17: Core - margined | C17: Example 5: multiplier | D17: CRE99 ex.5 | E17: Official published value (rounded) | F17: BCBS | G17: Results | H17: BCBS-EX5 | I17: Multiplier | J17: 0.958 | K17: abs | L17: 0.0005 | M17: =IFERROR(INDEX(Results!$A$5:$AA$3000,MATCH($H17,Results!$A$5:$A$3000,0),MATCH($I17,Results!$A$4:$AA$4,0)),"n/a") -> 0.95812333 | N17: =IF(AND(ISNUMBER(M17),ISNUMBER(J17)),M17-J17,"") -> 0.00012332739 | O17: =IF(K17="text",IF(M17&""=J17&"","PASS","FAIL"),IF(NOT(ISNUMBER(M17)),"FAIL",IF(K17="rel",IF(ABS(N17)<=L17*MAX(1,ABS(J17)),"PASS","FAIL"),IF(ABS(N17)<=L17,"PASS","FAIL")))) -> PASS
A18: T14 | B18: Core - margined | C18: Example 5: EAD | D18: CRE99 ex.5 | E18: Official published value (rounded) | F18: BCBS | G18: Results | H18: BCBS-EX5 | I18: EAD | J18: 1879 | K18: abs | L18: 0.5 | M18: =IFERROR(INDEX(Results!$A$5:$AA$3000,MATCH($H18,Results!$A$5:$A$3000,0),MATCH($I18,Results!$A$4:$AA$4,0)),"n/a") -> 1879.2126 | N18: =IF(AND(ISNUMBER(M18),ISNUMBER(J18)),M18-J18,"") -> 0.2126315 | O18: =IF(K18="text",IF(M18&""=J18&"","PASS","FAIL"),IF(NOT(ISNUMBER(M18)),"FAIL",IF(K18="rel",IF(ABS(N18)<=L18*MAX(1,ABS(J18)),"PASS","FAIL"),IF(ABS(N18)<=L18,"PASS","FAIL")))) -> PASS
A19: T15 | B19: EU - cap | C19: Example 5 under CRR: Art. 274(3) cap not binding, same EAD | D19: CRE99 ex.5 + CRR Art. 274(3) | E19: Derived - independent Python implementation | F19: CRR | G19: Results | H19: CRR-EX5 | I19: EAD | J19: 1879 | K19: abs | L19: 0.5 | M19: =IFERROR(INDEX(Results!$A$5:$AA$3000,MATCH($H19,Results!$A$5:$A$3000,0),MATCH($I19,Results!$A$4:$AA$4,0)),"n/a") -> 1879.2126 | N19: =IF(AND(ISNUMBER(M19),ISNUMBER(J19)),M19-J19,"") -> 0.2126315 | O19: =IF(K19="text",IF(M19&""=J19&"","PASS","FAIL"),IF(NOT(ISNUMBER(M19)),"FAIL",IF(K19="rel",IF(ABS(N19)<=L19*MAX(1,ABS(J19)),"PASS","FAIL"),IF(ABS(N19)<=L19,"PASS","FAIL")))) -> PASS | P19: Common core reproduces the Basel result
A20: T16 | B20: EU - cap | C20: Posted VM: Basel cap uses NICA only -> cap binds (~41) | D20: CRE52.2, CRE52.10 | E20: Engineering scenario - not authoritative | F20: BCBS | G20: Results | H20: BCBS-VMCAP | I20: EAD | J20: 40774849 | K20: rel | L20: 1e-09 | M20: =IFERROR(INDEX(Results!$A$5:$AA$3000,MATCH($H20,Results!$A$5:$A$3000,0),MATCH($I20,Results!$A$4:$AA$4,0)),"n/a") -> 40774849 | N20: =IF(AND(ISNUMBER(M20),ISNUMBER(J20)),M20-J20,"") -> 0 | O20: =IF(K20="text",IF(M20&""=J20&"","PASS","FAIL"),IF(NOT(ISNUMBER(M20)),"FAIL",IF(K20="rel",IF(ABS(N20)<=L20*MAX(1,ABS(J20)),"PASS","FAIL"),IF(ABS(N20)<=L20,"PASS","FAIL")))) -> PASS | P20: Same as T17 since #39: cap ~41 < margined ~377
A21: T17 | B21: EU - cap | C21: Posted VM: CRR cap excludes VM from NICA -> cap binds (~41) | D21: CRR Art. 274(3), 275(1); EBA Q&A 2023_6962 | E21: Engineering scenario - not authoritative | F21: CRR | G21: Results | H21: CRR-VMCAP | I21: EAD | J21: 40774849 | K21: rel | L21: 1e-09 | M21: =IFERROR(INDEX(Results!$A$5:$AA$3000,MATCH($H21,Results!$A$5:$A$3000,0),MATCH($I21,Results!$A$4:$AA$4,0)),"n/a") -> 40774849 | N21: =IF(AND(ISNUMBER(M21),ISNUMBER(J21)),M21-J21,"") -> 0 | O21: =IF(K21="text",IF(M21&""=J21&"","PASS","FAIL"),IF(NOT(ISNUMBER(M21)),"FAIL",IF(K21="rel",IF(ABS(N21)<=L21*MAX(1,ABS(J21)),"PASS","FAIL"),IF(ABS(N21)<=L21,"PASS","FAIL")))) -> PASS | P21: Q&A 2022_6354 illustration: 41 (cap) vs 378 (margined)
A22: T18 | B22: EU - cap | C22: Posted VM: cap applied flag | D22: EBA Q&A 2023_6962 | E22: Engineering scenario - not authoritative | F22: CRR | G22: Results | H22: CRR-VMCAP | I22: Cap applied | J22: Y | K22: text | L22: 0 | M22: =IFERROR(INDEX(Results!$A$5:$AA$3000,MATCH($H22,Results!$A$5:$A$3000,0),MATCH($I22,Results!$A$4:$AA$4,0)),"n/a") -> Y | N22: =IF(AND(ISNUMBER(M22),ISNUMBER(J22)),M22-J22,"") | O22: =IF(K22="text",IF(M22&""=J22&"","PASS","FAIL"),IF(NOT(ISNUMBER(M22)),"FAIL",IF(K22="rel",IF(ABS(N22)<=L22*MAX(1,ABS(J22)),"PASS","FAIL"),IF(ABS(N22)<=L22,"PASS","FAIL")))) -> PASS
A23: T19 | B23: EU - options | C23: Swaption forward 1%: EAD (lambda = 0) | D23: EBA SA-CCR RTS work, as cited (~761) | E23: Derived - independent Python implementation | F23: CRR | G23: Results | H23: CRR-EX1-1PCT | I23: EAD | J23: 760.49393 | K23: rel | L23: 1e-09 | M23: =IFERROR(INDEX(Results!$A$5:$AA$3000,MATCH($H23,Results!$A$5:$A$3000,0),MATCH($I23,Results!$A$4:$AA$4,0)),"n/a") -> 760.49393 | N23: =IF(AND(ISNUMBER(M23),ISNUMBER(J23)),M23-J23,"") -> 0 | O23: =IF(K23="text",IF(M23&""=J23&"","PASS","FAIL"),IF(NOT(ISNUMBER(M23)),"FAIL",IF(K23="rel",IF(ABS(N23)<=L23*MAX(1,ABS(J23)),"PASS","FAIL"),IF(ABS(N23)<=L23,"PASS","FAIL")))) -> PASS | P23: Cited figures: PFE ~483, EAD ~761 - source not opened here
A24: T20 | B24: EU - options | C24: Negative forward: RTS lambda = 0.10% - min(P, K) | D24: Del. Reg. 2021/931 Art. 5 (am. 2025/855) | E24: Hand calculation from the regulation | F24: CRR | G24: TradeCalc | H24: NIR-C | I24: Lambda | J24: 0.003 | K24: abs | L24: 1e-12 | M24: =IFERROR(INDEX(TradeCalc!$A$5:$Y$3000,MATCH($H24,TradeCalc!$A$5:$A$3000,0),MATCH($I24,TradeCalc!$A$4:$Y$4,0)),"n/a") -> 0.003 | N24: =IF(AND(ISNUMBER(M24),ISNUMBER(J24)),M24-J24,"") -> 0 | O24: =IF(K24="text",IF(M24&""=J24&"","PASS","FAIL"),IF(NOT(ISNUMBER(M24)),"FAIL",IF(K24="rel",IF(ABS(N24)<=L24*MAX(1,ABS(J24)),"PASS","FAIL"),IF(ABS(N24)<=L24,"PASS","FAIL")))) -> PASS
A25: T21 | B25: EU - options | C25: Negative forward: supervisory delta with shift | D25: Del. Reg. 2021/931 Art. 5 | E25: Derived - independent Python implementation | F25: CRR | G25: TradeCalc | H25: NIR-C | I25: Supervisory delta | J25: -0.99417527 | K25: rel | L25: 1e-09 | M25: =IFERROR(INDEX(TradeCalc!$A$5:$Y$3000,MATCH($H25,TradeCalc!$A$5:$A$3000,0),MATCH($I25,TradeCalc!$A$4:$Y$4,0)),"n/a") -> -0.99417527 | N25: =IF(AND(ISNUMBER(M25),ISNUMBER(J25)),M25-J25,"") -> 0 | O25: =IF(K25="text",IF(M25&""=J25&"","PASS","FAIL"),IF(NOT(ISNUMBER(M25)),"FAIL",IF(K25="rel",IF(ABS(N25)<=L25*MAX(1,ABS(J25)),"PASS","FAIL"),IF(ABS(N25)<=L25,"PASS","FAIL")))) -> PASS
A26: T22 | B26: Basel - options | C26: Negative forward without lambda under BCBS is rejected | D26: CRE52.40 FAQ (lambda by judgement) | E26: Hand calculation from the regulation | F26: BCBS | G26: TradeCalc | H26: NIR-B | I26: Status | J26: EXCLUDED | K26: text | L26: 0 | M26: =IFERROR(INDEX(TradeCalc!$A$5:$Y$3000,MATCH($H26,TradeCalc!$A$5:$A$3000,0),MATCH($I26,TradeCalc!$A$4:$Y$4,0)),"n/a") -> EXCLUDED | N26: =IF(AND(ISNUMBER(M26),ISNUMBER(J26)),M26-J26,"") | O26: =IF(K26="text",IF(M26&""=J26&"","PASS","FAIL"),IF(NOT(ISNUMBER(M26)),"FAIL",IF(K26="rel",IF(ABS(N26)<=L26*MAX(1,ABS(J26)),"PASS","FAIL"),IF(ABS(N26)<=L26,"PASS","FAIL")))) -> PASS | P26: Enter lambda on the trade for BCBS
A27: T23 | B27: EU - options | C27: Negative commodity price: lambda = -(1 + 0.1) x min(P, K) | D27: Del. Reg. 2021/931 Art. 5 (am. 2025/855) | E27: Hand calculation from the regulation | F27: CRR | G27: TradeCalc | H27: NCO-1 | I27: Lambda | J27: 5.5 | K27: abs | L27: 1e-12 | M27: =IFERROR(INDEX(TradeCalc!$A$5:$Y$3000,MATCH($H27,TradeCalc!$A$5:$A$3000,0),MATCH($I27,TradeCalc!$A$4:$Y$4,0)),"n/a") -> 5.5 | N27: =IF(AND(ISNUMBER(M27),ISNUMBER(J27)),M27-J27,"") -> 0 | O27: =IF(K27="text",IF(M27&""=J27&"","PASS","FAIL"),IF(NOT(ISNUMBER(M27)),"FAIL",IF(K27="rel",IF(ABS(N27)<=L27*MAX(1,ABS(J27)),"PASS","FAIL"),IF(ABS(N27)<=L27,"PASS","FAIL")))) -> PASS
A28: T24 | B28: EU - other risks | C28: Other risks add-on = 8% x (|6,000| + |5,000|) | D28: CRR Art. 280f | E28: Hand calculation from the regulation | F28: CRR | G28: Results | H28: CRR-OTHER | I28: AddOn OT | J28: 880 | K28: abs | L28: 1e-09 | M28: =IFERROR(INDEX(Results!$A$5:$AA$3000,MATCH($H28,Results!$A$5:$A$3000,0),MATCH($I28,Results!$A$4:$AA$4,0)),"n/a") -> 880 | N28: =IF(AND(ISNUMBER(M28),ISNUMBER(J28)),M28-J28,"") -> 0 | O28: =IF(K28="text",IF(M28&""=J28&"","PASS","FAIL"),IF(NOT(ISNUMBER(M28)),"FAIL",IF(K28="rel",IF(ABS(N28)<=L28*MAX(1,ABS(J28)),"PASS","FAIL"),IF(ABS(N28)<=L28,"PASS","FAIL")))) -> PASS
A29: T25 | B29: EU - other risks | C29: Other risks EAD = 1.4 x 880 | D29: CRR Art. 274(2), 280f | E29: Hand calculation from the regulation | F29: CRR | G29: Results | H29: CRR-OTHER | I29: EAD | J29: 1232 | K29: abs | L29: 1e-09 | M29: =IFERROR(INDEX(Results!$A$5:$AA$3000,MATCH($H29,Results!$A$5:$A$3000,0),MATCH($I29,Results!$A$4:$AA$4,0)),"n/a") -> 1232 | N29: =IF(AND(ISNUMBER(M29),ISNUMBER(J29)),M29-J29,"") -> 0 | O29: =IF(K29="text",IF(M29&""=J29&"","PASS","FAIL"),IF(NOT(ISNUMBER(M29)),"FAIL",IF(K29="rel",IF(ABS(N29)<=L29*MAX(1,ABS(J29)),"PASS","FAIL"),IF(ABS(N29)<=L29,"PASS","FAIL")))) -> PASS
A30: T26 | B30: Basel - other risks | C30: Other-risks trade in a BCBS netting set is rejected | D30: CRE52 (five asset classes) | E30: Hand calculation from the regulation | F30: BCBS | G30: TradeCalc | H30: OT-X | I30: Status | J30: EXCLUDED | K30: text | L30: 0 | M30: =IFERROR(INDEX(TradeCalc!$A$5:$Y$3000,MATCH($H30,TradeCalc!$A$5:$A$3000,0),MATCH($I30,TradeCalc!$A$4:$Y$4,0)),"n/a") -> EXCLUDED | N30: =IF(AND(ISNUMBER(M30),ISNUMBER(J30)),M30-J30,"") | O30: =IF(K30="text",IF(M30&""=J30&"","PASS","FAIL"),IF(NOT(ISNUMBER(M30)),"FAIL",IF(K30="rel",IF(ABS(N30)<=L30*MAX(1,ABS(J30)),"PASS","FAIL"),IF(ABS(N30)<=L30,"PASS","FAIL")))) -> PASS
A31: T27 | B31: EU - mapping | C31: Climatic variable mapped to its own commodity hedging set | D31: CRR Art. 277(4)(b), 277a | E31: Hand calculation from the regulation | F31: CRR | G31: TradeCalc | H31: CL-1 | I31: Hedging set | J31: CO|CLIMATIC|STD | K31: text | L31: 0 | M31: =IFERROR(INDEX(TradeCalc!$A$5:$Y$3000,MATCH($H31,TradeCalc!$A$5:$A$3000,0),MATCH($I31,TradeCalc!$A$4:$Y$4,0)),"n/a") -> CO|CLIMATIC|STD | N31: =IF(AND(ISNUMBER(M31),ISNUMBER(J31)),M31-J31,"") | O31: =IF(K31="text",IF(M31&""=J31&"","PASS","FAIL"),IF(NOT(ISNUMBER(M31)),"FAIL",IF(K31="rel",IF(ABS(N31)<=L31*MAX(1,ABS(J31)),"PASS","FAIL"),IF(ABS(N31)<=L31,"PASS","FAIL")))) -> PASS | P31: SF value to be confirmed against Art. 280e
A32: T28 | B32: EU - mapping | C32: Credit quality step 2 -> SF 0.42% | D32: CRR Art. 280c Table 3 | E32: Hand calculation from the regulation | F32: CRR | G32: TradeCalc | H32: B03 | I32: SF (effective) | J32: 0.0042 | K32: abs | L32: 1e-12 | M32: =IFERROR(INDEX(TradeCalc!$A$5:$Y$3000,MATCH($H32,TradeCalc!$A$5:$A$3000,0),MATCH($I32,TradeCalc!$A$4:$Y$4,0)),"n/a") -> 0.0042 | N32: =IF(AND(ISNUMBER(M32),ISNUMBER(J32)),M32-J32,"") -> 0 | O32: =IF(K32="text",IF(M32&""=J32&"","PASS","FAIL"),IF(NOT(ISNUMBER(M32)),"FAIL",IF(K32="rel",IF(ABS(N32)<=L32*MAX(1,ABS(J32)),"PASS","FAIL"),IF(ABS(N32)<=L32,"PASS","FAIL")))) -> PASS
B34: Summary | C34: =COUNTIF(O5:O32,"PASS")&" passed, "&COUNTIF(O5:O32,"FAIL")&" failed of "&COUNTA(A5:A32) -> 28 passed, 0 failed of 28
B36: Source status: "Official" = published figure, rounded (tolerance covers rounding); "Hand calculation" = derived directly from the legal text; "Derived" / "Engineering scenario" = expected value from an independent Python implementation of the same rules - a regression anchor, not an external authority.
B37: Engineering scenarios after EBA Q&A 2022_6354 (rejected) reproduce its pattern only; the decisive rule is the final Q&A 2023_6962. The EBA swaption figures (~483 / ~761) are as cited in the project note.
B38: Not yet in the catalogue: CRE99 margin-agreement / RC examples (segregated vs non-segregated IM), unrated credit mapping. One-way CSA, the client clearing role and the margin-agreement structures are tested in TEST_InputValidation (#39); several margin agreements per netting set and one agreement over several netting sets are rejected, not modelled.

Sheet Tests
A1: Tests
A2: Unit tests call the SACCR_* worksheet functions (macros enabled); portfolio tests are on TestCatalogue.
A4: Unit tests of the worksheet functions
A5: Test | B5: Formula | C5: Expected | D5: Function | E5: Abs. diff | F5: Result
A6: Supervisory duration, S=0, E=10 | B6: =SACCR_SupervisoryDuration(0,10) | C6: 7.8693868 | D6: =SACCR_SupervisoryDuration(0,10) -> 7.8693868 | E6: =IFERROR(ABS(D6-C6),"") -> 0 | F6: =IF(ISNUMBER(E6),IF(E6<=1E-9*MAX(1,ABS(C6)),"PASS","FAIL"),"FAIL") -> PASS
A7: Supervisory duration, S=1, E=11 | B7: =SACCR_SupervisoryDuration(1,11) | C7: 7.4855923 | D7: =SACCR_SupervisoryDuration(1,11) -> 7.4855923 | E7: =IFERROR(ABS(D7-C7),"") -> 0 | F7: =IF(ISNUMBER(E7),IF(E7<=1E-9*MAX(1,ABS(C7)),"PASS","FAIL"),"FAIL") -> PASS
A8: SD floor, S=0, E=0.01 (floor 10/250) | B8: =SACCR_SupervisoryDuration(0,0.01,10/250) | C8: 0.04 | D8: =SACCR_SupervisoryDuration(0,0.01,10/250) -> 0.04 | E8: =IFERROR(ABS(D8-C8),"") -> 0 | F8: =IF(ISNUMBER(E8),IF(E8<=1E-9*MAX(1,ABS(C8)),"PASS","FAIL"),"FAIL") -> PASS
A9: MF unmargined, M=0.75 | B9: =SACCR_MaturityFactor(0.75) | C9: 0.8660254 | D9: =SACCR_MaturityFactor(0.75) -> 0.8660254 | E9: =IFERROR(ABS(D9-C9),"") -> 0 | F9: =IF(ISNUMBER(E9),IF(E9<=1E-9*MAX(1,ABS(C9)),"PASS","FAIL"),"FAIL") -> PASS
A10: MF unmargined, M=3 days (floor 10 BD) | B10: =SACCR_MaturityFactor(3/365) | C10: 0.2 | D10: =SACCR_MaturityFactor(3/365) -> 0.2 | E10: =IFERROR(ABS(D10-C10),"") -> 0 | F10: =IF(ISNUMBER(E10),IF(E10<=1E-9*MAX(1,ABS(C10)),"PASS","FAIL"),"FAIL") -> PASS
A11: MF margined, MPOR=10 BD | B11: =SACCR_MaturityFactor(0,TRUE,10) | C11: 0.3 | D11: =SACCR_MaturityFactor(0,TRUE,10) -> 0.3 | E11: =IFERROR(ABS(D11-C11),"") -> 0 | F11: =IF(ISNUMBER(E11),IF(E11<=1E-9*MAX(1,ABS(C11)),"PASS","FAIL"),"FAIL") -> PASS
A12: Delta, bought put P=6% K=5% T=1 vol=50% | B12: =SACCR_OptionDelta(0.06,0.05,1,0.5,FALSE,TRUE) | C12: -0.26939522 | D12: =SACCR_OptionDelta(0.06,0.05,1,0.5,FALSE,TRUE) -> -0.26939522 | E12: =IFERROR(ABS(D12-C12),"") -> 0 | F12: =IF(ISNUMBER(E12),IF(E12<=1E-9*MAX(1,ABS(C12)),"PASS","FAIL"),"FAIL") -> PASS
A13: Delta, sold call P=100 K=110 T=0.5 vol=32% | B13: =SACCR_OptionDelta(100,110,0.5,0.32,TRUE,FALSE) | C13: -0.37901135 | D13: =SACCR_OptionDelta(100,110,0.5,0.32,TRUE,FALSE) -> -0.37901135 | E13: =IFERROR(ABS(D13-C13),"") -> 0 | F13: =IF(ISNUMBER(E13),IF(E13<=1E-9*MAX(1,ABS(C13)),"PASS","FAIL"),"FAIL") -> PASS
A14: Delta with lambda shift, P=-0.2% K=0.1% L=1% | B14: =SACCR_OptionDelta(-0.002,0.001,2,0.5,TRUE,TRUE,0.01) | C14: 0.46143936 | D14: =SACCR_OptionDelta(-0.002,0.001,2,0.5,TRUE,TRUE,0.01) -> 0.46143936 | E14: =IFERROR(ABS(D14-C14),"") -> 0 | F14: =IF(ISNUMBER(E14),IF(E14<=1E-9*MAX(1,ABS(C14)),"PASS","FAIL"),"FAIL") -> PASS
A15: CDO delta, 3-6% tranche, long | B15: =SACCR_CDODelta(0.03,0.06,TRUE) | C15: 5.7409675 | D15: =SACCR_CDODelta(0.03,0.06,TRUE) -> 5.7409675 | E15: =IFERROR(ABS(D15-C15),"") -> 0 | F15: =IF(ISNUMBER(E15),IF(E15<=1E-9*MAX(1,ABS(C15)),"PASS","FAIL"),"FAIL") -> PASS
A16: IR effective notional, Basel ex.1 USD | B16: =SACCR_IREffectiveNotional(0.0,-36253.849384403635,78693.86805747332) | C16: 59269.963 | D16: =SACCR_IREffectiveNotional(0.0,-36253.849384403635,78693.86805747332) -> 59269.963 | E16: =IFERROR(ABS(D16-C16),"") -> 0 | F16: =IF(ISNUMBER(E16),IF(E16<=1E-9*MAX(1,ABS(C16)),"PASS","FAIL"),"FAIL") -> PASS
A17: Factor aggregation, Basel ex.2 | B17: =SACCR_FactorAggregation({105.86193791695607,-279.91632166374467,168.11140486573228},{0.5,0.5,0.8}) | C17: 282.12883 | D17: =SACCR_FactorAggregation({105.86193791695607,-279.91632166374467,168.11140486573228},{0.5,0.5,0.8}) -> 282.12883 | E17: =IFERROR(ABS(D17-C17),"") -> 0 | F17: =IF(ISNUMBER(E17),IF(E17<=1E-9*MAX(1,ABS(C17)),"PASS","FAIL"),"FAIL") -> PASS
A18: Multiplier, V-C=-20, AddOn=282 | B18: =SACCR_Multiplier(-20,282) | C18: 0.96519268 | D18: =SACCR_Multiplier(-20,282) -> 0.96519268 | E18: =IFERROR(ABS(D18-C18),"") -> 0 | F18: =IF(ISNUMBER(E18),IF(E18<=1E-9*MAX(1,ABS(C18)),"PASS","FAIL"),"FAIL") -> PASS
A19: Multiplier, V-C>0 | B19: =SACCR_Multiplier(10,282) | C19: 1 | D19: =SACCR_Multiplier(10,282) -> 1 | E19: =IFERROR(ABS(D19-C19),"") -> 0 | F19: =IF(ISNUMBER(E19),IF(E19<=1E-9*MAX(1,ABS(C19)),"PASS","FAIL"),"FAIL") -> PASS
A20: RC margined, V-C=-5, TH=0, MTA=10, NICA=2 | B20: =SACCR_ReplacementCost(5,10,TRUE,0,10,2) | C20: 8 | D20: =SACCR_ReplacementCost(5,10,TRUE,0,10,2) -> 8 | E20: =IFERROR(ABS(D20-C20),"") -> 0 | F20: =IF(ISNUMBER(E20),IF(E20<=1E-9*MAX(1,ABS(C20)),"PASS","FAIL"),"FAIL") -> PASS
A21: Normal CDF(1.96) | B21: =SACCR_NormCDF(1.96) | C21: 0.9750021 | D21: =SACCR_NormCDF(1.96) -> 0.9750021 | E21: =IFERROR(ABS(D21-C21),"") -> 0 | F21: =IF(ISNUMBER(E21),IF(E21<=1E-9*MAX(1,ABS(C21)),"PASS","FAIL"),"FAIL") -> PASS
A22: Normal CDF(-8) | B22: =SACCR_NormCDF(-8) | C22: 6.2209606e-16 | D22: =SACCR_NormCDF(-8) -> 6.2209606e-16 | E22: =IFERROR(ABS(D22-C22),"") -> 0 | F22: =IF(ISNUMBER(E22),IF(E22<=1E-9*MAX(1,ABS(C22)),"PASS","FAIL"),"FAIL") -> PASS
A23: CRR lambda IR, P=-0.20% K=0.10% | B23: =SACCR_LambdaCRR(-0.002,0.001,TRUE) | C23: 0.003 | D23: =SACCR_LambdaCRR(-0.002,0.001,TRUE) -> 0.003 | E23: =IFERROR(ABS(D23-C23),"") -> 0 | F23: =IF(ISNUMBER(E23),IF(E23<=1E-9*MAX(1,ABS(C23)),"PASS","FAIL"),"FAIL") -> PASS
A24: CRR lambda IR, P=2% K=3% (no shift) | B24: =SACCR_LambdaCRR(0.02,0.03,TRUE) | C24: 0 | D24: =SACCR_LambdaCRR(0.02,0.03,TRUE) -> 0 | E24: =IFERROR(ABS(D24-C24),"") -> 0 | F24: =IF(ISNUMBER(E24),IF(E24<=1E-9*MAX(1,ABS(C24)),"PASS","FAIL"),"FAIL") -> PASS
A25: CRR lambda IR, P=0.05% K=1% (to threshold) | B25: =SACCR_LambdaCRR(0.0005,0.01,TRUE) | C25: 0.0005 | D25: =SACCR_LambdaCRR(0.0005,0.01,TRUE) -> 0.0005 | E25: =IFERROR(ABS(D25-C25),"") -> 0 | F25: =IF(ISNUMBER(E25),IF(E25<=1E-9*MAX(1,ABS(C25)),"PASS","FAIL"),"FAIL") -> PASS
A26: CRR lambda commodity, P=-5 K=-4 | B26: =SACCR_LambdaCRR(-5,-4,FALSE) | C26: 5.5 | D26: =SACCR_LambdaCRR(-5,-4,FALSE) -> 5.5 | E26: =IFERROR(ABS(D26-C26),"") -> 0 | F26: =IF(ISNUMBER(E26),IF(E26<=1E-9*MAX(1,ABS(C26)),"PASS","FAIL"),"FAIL") -> PASS
A27: CRR lambda commodity, P=40 K=35 (no shift) | B27: =SACCR_LambdaCRR(40,35,FALSE) | C27: 0 | D27: =SACCR_LambdaCRR(40,35,FALSE) -> 0 | E27: =IFERROR(ABS(D27-C27),"") -> 0 | F27: =IF(ISNUMBER(E27),IF(E27<=1E-9*MAX(1,ABS(C27)),"PASS","FAIL"),"FAIL") -> PASS

Sheet Basel_vs_CRR
A1: Basel CRE52 vs EU CRR
A2: EU text: CRR consolidated version of 26/06/2026 (Art. 273a-282), Delegated Regulation (EU) 2021/931 as amended by (EU) 2025/855, EBA Q&A. Basel: CRE52, its FAQs and the CRE99 / BCBS 279 examples.
A4: # | B4: Area | C4: Basel CRE52 | D4: EU CRR | E4: Same / different | F4: Effect on numbers | G4: Workbook treatment | H4: Tests | I4: Source check
A5: 1 | B5: Normative hierarchy | C5: CRE52 + CRE52 FAQs; CRE99 / BCBS 279 Annex 4 worked examples. | D5: CRR Art. 273a-282 (Level 1) -> Delegated Reg. (EU) 2021/931 as amended (incl. 2025/855) -> EBA Q&A. | E5: Different | F5: Interpretation route | G5: Regime on Params (default CRR), override per netting set. Regime rules sit in the engine, not inside the SACCR_* formula functions. | H5: - | I5: VERIFIED
A6: 2 | B6: EAD and alpha | C6: EAD = 1.4 x (RC + PFE) [CRE52.1]. | D6: Art. 274(2): alpha = 1.4; the consolidated text has no alpha exception by counterparty type. | E6: Same | F6: None | G6: Common core. Alpha override per netting set exists only for what-if use. | H6: T04 | I6: VERIFIED
A7: 3 | B7: Cap of margined EAD | C7: Capped at the EAD of the same netting set "calculated on an unmargined basis" [CRE52.2]; unmargined C is the NICA collateral [CRE52.10], so the cap uses NICA only. | D7: Art. 274(3): capped at the exposure of the same netting set "not subject to any form of margin agreement". RC per Art. 275(1); NICA does not include VM posted or received (EBA Q&A 2023_6962, final, 15/03/2024). | E7: Same | F7: None since #39: both caps use NICA (posted-VM scenario ~41m in both regimes). | G7: Implemented. Cap: C(cap) = NICA for RC and multiplier in both regimes. Results shows C, RC and multiplier on the cap basis. | H7: T15-T18 | I7: VERIFIED (CRE52.2, CRE52.10; CRR, Q&A)
A8: 4 | B8: RC - unmargined | C8: RC = max(V - C, 0) [CRE52.10]; a one-way agreement where only the bank posts VM is unmargined, and C includes that VM with a negative sign [CRE52.2, CRE52.10 footnote 2]. | D8: RC = max(CMV - NICA, 0) [Art. 275(1)]; collateral per CRR definitions (Art. 272(12a), 276). A one-way margin agreement is a margin agreement [Art. 272(7a)]: the netting set is margined. | E8: Different (one-way agreement) | F8: One-way agreements where the bank posts VM | G8: Enter collateral after haircuts, in NICA. VM held on an unmargined set is rejected. VM posted (one-way agreement): BCBS includes it in C; CRR rejects it - set Margined = Y. | H8: T08 | I8: VERIFIED
A9: 5 | B9: RC - margined | C9: RC = max(V - C, TH + MTA - NICA, 0) [CRE52.18]. | D9: RC = max(CMV - VM - NICA, TH + MTA - NICA, 0) [Art. 275(2)]. | E9: Same | F9: None | G9: Common core. | H9: T14 | I9: VERIFIED
A10: 6 | B10: Multiplier | C10: min(1; 5% + 95% exp((V - C) / (2 x 95% x AddOn))) [CRE52.23]. | D10: Art. 278(3): same; z = CMV - VM - NICA (margined), CMV - NICA (unmargined). | E10: Same | F10: None | G10: Common core. | H10: T05, T13 | I10: VERIFIED
A11: 7 | B11: Asset classes | C11: Five: IR, FX, credit, equity, commodity. | D11: Six: adds "other risks" [Art. 277(1)(f)]. | E11: Different | F11: Additional add-on | G11: Asset class OT, allowed only in CRR netting sets; rejected (Checks) under BCBS. | H11: T24-T26 | I11: VERIFIED
A12: 8 | B12: Other-risks add-on | C12: No equivalent. | D12: Art. 280f: per hedging set, AddOn = coefficient x 8% x |effective notional|; supervisory option volatility 150% [Art. 279a Table 1]. | E12: EU only | F12: New add-on | G12: Hedging set per primary risk driver (risk-factor text) and nature; FX-style aggregation. | H12: T24, T25 | I12: VERIFIED (SF, vol); hedging-set wording OPEN
A13: 9 | B13: Risk-driver mapping | C13: Primary risk driver; for complex trades supervisors may require allocation to more than one class. | D13: Art. 277(2)-(3): one vs several material risk drivers, mapped once per risk category; method fixed in Delegated Reg. (EU) 2021/931. | E13: Different (EU prescriptive) | F13: Classification of hybrids | G13: Not automated: enter one row per risk-category leg, classified per the RTS. | H13: - | I13: VERIFIED
A14: 10 | B14: Commodity hedging sets | C14: Energy, metals, agricultural, other [CRE52.70]; no specific rule for weather. | D14: Energy, metals, agricultural goods, other, climatic conditions [Art. 277a]; climatic variables mapped to commodity [Art. 277(4)(b)]. | E14: Different | F14: Climatic trades no longer offset against "other" | G14: CO sub-class CLIMATIC (CRR-only row, own hedging set). | H14: T27 | I14: VERIFIED: 18% [Art. 280e(5)]
A15: 11 | B15: Inflation | C15: Basel FAQ: interest-rate class, separate hedging set per currency, SF 0.5%. | D15: Mapped to interest rate. | E15: Same numbers | F15: None expected | G15: Enter as IR; a distinct risk-factor label (e.g. EUR-INFL) gives a separate hedging set. | H15: - | I15: VERIFIED (CRR Art. 277(4)(a), 277a(1))
A16: 12 | B16: Option delta - negative rates / prices | C16: Shift lambda = "presumed lowest possible extent" rates can become negative - judgement [CRE52.40 FAQ2]. | D16: Delegated Reg. 2021/931 Art. 5 (am. 2025/855), per option: IR lambda = max(0.10% - min(P,K); 0); commodity lambda = max(-(1 + 0.1) x min(P,K); 0). | E16: Different | F16: Delta differs when P or K is near or below zero | G16: CRR: lambda computed (input ignored with a warning). BCBS: lambda from the trade; rejected if P or K + lambda <= 0. | H16: T20-T23 | I16: VERIFIED (EBA/RTS/2024/16; OJ 2025/855)
... A29: 25 | B29: Collateral eligibility and haircuts | C29: Basel credit risk mitigation framework. | D29: Art. 276 with the CRR collateral rules (e.g. Art. 223). | E29: Different rules | F29: Collateral values | G29: Collateral is an input after haircuts. | H29: - | I29: CITED
